<?xml version="1.0" ?>

<robot name="my_robot" xmlns:xacro="http://www.ros.org/wiki/xacro">
<!-- The root link robot_base has an inertia specified in the URDF,
 but KDL does not support a root link with an inertia.  As a workaround,
  adding an extra dummy link to URDF-->
  <link name="Dummy_link"></link>

    <xacro:include filename="$(find my_robot)/urdf/my_robot.gazebo" />

  <joint name="Dummy_link_robot_base" type="fixed">
    <origin xyz="0 0 0" rpy="0 0 0" />
    <parent link="Dummy_link"/>
    <child link="robot_base" />
  </joint>

  <link name="robot_base">
    <inertial>
      <mass value="5"/>
      <origin rpy="0  0  0" xyz="0  0  0"/>
      <inertia ixx="0.145833" ixy="0" ixz="0" iyy="0.145833" iyz="0" izz="0.125"/>
    </inertial>
    <collision name="robot_base_collision">
      <origin rpy="0  0  0" xyz="0  0  0"/>
      <geometry>
        <cylinder length="0.25" radius="0.3"/>
      </geometry>
    </collision>
    <visual name="my_robot_visual">
      <origin rpy="0  0  0" xyz="0  0  0"/>
      <geometry>
        <cylinder length="0.25" radius="0.3"/>
      </geometry>
    </visual>
  </link>

  <link name="robot_middle_plate">
    <inertial>
      <mass value="0.5"/>
      <origin rpy="0  0  0" xyz="0  0  0"/>
      <inertia ixx="0.145833" ixy="0" ixz="0" iyy="0.145833" iyz="0" izz="0.125"/>
    </inertial>
    <collision name="robot_middle_plate_collision">
      <origin rpy="0  0  0" xyz="0  0  0"/>
      <geometry>
        <cylinder length="0.05" radius="0.3"/>
      </geometry>
    </collision>
    <visual name="robot_middle_plate_visual">
      <origin rpy="0  0  0" xyz="0  0  0"/>
      <geometry>
        <cylinder length="0.05" radius="0.3"/>
      </geometry>
    </visual>
  </link>
  <joint name="robot_base_robot_top_plate" type="fixed">
    <parent link="robot_base"/>
    <child link="robot_top_plate"/>
    <origin rpy="0  0  0" xyz="-0.01262  0       0.82481"/>
    <axis xyz="0  0  0"/>
    <limit effort="0" lower="0" upper="0" velocity="0"/>
  </joint>
  
  <link name="robot_top_plate">
    <inertial>
      <mass value="0.3"/>
      <origin rpy="0  0  0" xyz="0  0  0"/>
      <inertia ixx="0.145833" ixy="0" ixz="0" iyy="0.145833" iyz="0" izz="0.125"/>
    </inertial>
    <collision name="robot_top_plate_collision">
      <origin rpy="0  0  0" xyz="0  0  0"/>
      <geometry>
        <cylinder length="0.05" radius="0.3"/>
      </geometry>
    </collision>
    <visual name="robot_top_plate_visual">
      <origin rpy="0  0  0" xyz="0  0  0"/>
      <geometry>
        <cylinder length="0.05" radius="0.3"/>
      </geometry>
    </visual>
  </link>
  <joint name="robot_bas_robot_middle_plate" type="fixed">
    <parent link="robot_base"/>
    <child link="robot_middle_plate"/>
    <origin rpy="0  0  0" xyz="-0.00756  0       0.47489"/>
    <axis xyz="0  0  0"/>
    <limit effort="0" lower="0" upper="0" velocity="0"/>
  </joint>


  <link name="hokuyo">

    <pose>0 0 0 0 0 0</pose>

    <inertial>
      <mass value="1e-6"/>
      <origin xyz="0.0 0 0" rpy=" 0 0 0"/>
      <inertia
          ixx="1e-6" ixy="0" ixz="0"
          iyy="1e-6" iyz="0"
          izz="1e-6"
      />
    </inertial>

    <collision name='hokuyo_collision'> 
      <origin xyz="0.0 0 0" rpy=" 0 0 0"/>      
      <geometry>
        <box size="0.1 0.1 0.1"/>
      </geometry>
      <mass value="1e-5"/>
    </collision>

    <visual name='hokuyo_visual'> 
      <origin xyz="0.0 0 0" rpy=" 0 0 0"/>  
      <geometry>
        <mesh filename="package://my_robot/meshes/hokuyo.dae"/>
      </geometry>
      <mass value="1e-5"/>
    </visual>
  
  </link>

  <joint type="fixed" name="hokuyo_joint">
    <origin xyz="0.0 0 0.2" rpy="0 0 0"/>
    <child link="hokuyo"/>
    <parent link="robot_base"/>
    <axis xyz="0 1 0" rpy="0 0 0"/>
  </joint>

  <link name="robot_left_support">
    <inertial>
      <mass value="0.1"/>
      <origin rpy="0  0  0" xyz="0  0  0"/>
      <inertia ixx="0.145833" ixy="0" ixz="0" iyy="0.145833" iyz="0" izz="0.125"/>
    </inertial>
    <collision name="robot_left_support_collision">
      <origin rpy="0  0  0" xyz="0  0  0"/>
      <geometry>
        <cylinder length="0.72" radius="0.01"/>
      </geometry>
    </collision>
    <visual name="robot_left_support_visual">
      <origin rpy="0  0  0" xyz="0  0  0"/>
      <geometry>
        <cylinder length="0.72" radius="0.01"/>
      </geometry>
    </visual>
  </link>
  <joint name="robot_base_robot_right_support" type="fixed">
    <parent link="robot_base"/>
    <child link="robot_right_support"/>
    <origin rpy="0  0  0" xyz="0.27   0     0.475"/>
    <axis xyz="0  0  0"/>
    <limit effort="0" lower="0" upper="0" velocity="0"/>
  </joint>

  <link name="robot_back_support">
    <inertial>
      <mass value="0.1"/>
      <origin rpy="0  0  0" xyz="0  0  0"/>
      <inertia ixx="0.145833" ixy="0" ixz="0" iyy="0.145833" iyz="0" izz="0.125"/>
    </inertial>
    <collision name="robot_back_support_collision">
      <origin rpy="0  0  0" xyz="0  0  0"/>
      <geometry>
        <cylinder length="0.72" radius="0.01"/>
      </geometry>
    </collision>
    <visual name="robot_back_support_visual">
      <origin rpy="0  0  0" xyz="0  0  0"/>
      <geometry>
        <cylinder length="0.72" radius="0.01"/>
      </geometry>
    </visual>
  </link>
   <joint name="robot_base_robot_back_support" type="fixed">
    <parent link="robot_base"/>
    <child link="robot_back_support"/>
    <origin rpy="0  0  0" xyz="0    -0.27   0.475"/>
    <axis xyz="0  0  0"/>
    <limit effort="0" lower="0" upper="0" velocity="0"/>
  </joint>
  
  <link name="robot_right_support">
    <inertial>
      <mass value="0.1"/>
      <origin rpy="0  0  0" xyz="0  0  0"/>
      <inertia ixx="0.145833" ixy="0" ixz="0" iyy="0.145833" iyz="0" izz="0.125"/>
    </inertial>
    <collision name="robot_right_support_collision">
      <origin rpy="0  0  0" xyz="0  0  0"/>
      <geometry>
        <cylinder length="0.72" radius="0.01"/>
      </geometry>
    </collision>
    <visual name="robot_right_support_visual">
      <origin rpy="0  0  0" xyz="0  0  0"/>
      <geometry>
        <cylinder length="0.72" radius="0.01"/>
      </geometry>
    </visual>
  </link>
  <joint name="robot_base_robot_left_support" type="fixed">
    <parent link="robot_base"/>
    <child link="robot_left_support"/>
    <origin rpy="0  0  0" xyz="-0.27   0     0.475"/>
    <axis xyz="0  0  0"/>
    <limit effort="0" lower="0" upper="0" velocity="0"/>
  </joint>

  <link name="front_caster">
    <inertial>
      <mass value="0.1"/>
      <origin rpy="0  0  0" xyz="0  0  0"/>
      <inertia ixx="0.1" ixy="0" ixz="0" iyy="0.1" iyz="0" izz="0.1"/>
    </inertial>
    <collision name="front_caster_collision">
      <origin rpy="0  0  0" xyz="0  0  0"/>
      <geometry>
        <sphere radius="0.0605"/>
      </geometry>
    </collision>
    <visual name="front_caster_visual">
      <origin rpy="0  0  0" xyz="0  0  0"/>
      <geometry>
        <sphere radius="0.0605"/>
      </geometry>
    </visual>
  </link>
  <joint name="robot_base_front_caster" type="fixed">
    <parent link="robot_base"/>
    <child link="front_caster"/>
    <origin rpy="0  0  0" xyz="0     0.245   -0.118"/>
    <axis xyz="0  0  0"/>
    <limit effort="0" lower="0" upper="0" velocity="0"/>
  </joint>

  <link name="back_caster">
    <inertial>
      <mass value="0.1"/>
      <origin rpy="0  0  0" xyz="0  0  0"/>
      <inertia ixx="0.1" ixy="0" ixz="0" iyy="0.1" iyz="0" izz="0.1"/>
    </inertial>
    <collision name="back_caster_collision">
      <origin rpy="0  0  0" xyz="0  0  0"/>
      <geometry>
        <sphere radius="0.0605"/>
      </geometry>
    </collision>
    <visual name="back_caster_visual">
      <origin rpy="0  0  0" xyz="0  0  0"/>
      <geometry>
        <sphere radius="0.0605"/>
      </geometry>
    </visual>
  </link>
  <joint name="robot_base_back_caster" type="fixed">
    <parent link="robot_base"/>
    <child link="back_caster"/>
    <origin rpy="0  0  0" xyz="0     -0.245   -0.118"/>
    <axis xyz="0  0  0"/>
    <limit effort="0" lower="0" upper="0" velocity="0"/>
  </joint>

  <link name="left_wheel">
    <pose>0 0 0.1 0 0 0</pose>

    <inertial>
      <mass value="1"/>
      <origin xyz="0.0 0 0" rpy="0 -1.5707  0"/>
      <inertia
          ixx="0.1" ixy="0" ixz="0"
          iyy="0.1" iyz="0"
          izz="0.1"
      />
    </inertial>

    <collision name='left_wheel_collision'>
      <origin xyz="0 0 0" rpy="0 -1.5707  0"/> 
      <geometry>
        <cylinder radius="0.055" length="0.03"/>
      </geometry>
    </collision>
    <visual name='left_wheel_visual'>
      <origin xyz="0 0 0" rpy="0 -1.5707  0"/> 
      <geometry>
        <cylinder radius="0.055" length="0.03"/>
      </geometry>
    </visual>
  </link>
  <joint name="left_wheel_hinge" type="continuous">
    <parent link="robot_base"/>
    <child link="left_wheel"/>
    <origin rpy="0  0  0" xyz="0.33   0    -0.125"/>
 <axis xyz="1 0 0" rpy="0 0 0"/>
    <limit effort="10000" velocity="1000"/>
    <dynamics damping="1.0" friction="1.0"/>
  </joint>

  <link name="right_wheel">
    <pose>0 0 0.1 0 0 0</pose>

    <inertial>
      <mass value="1.0"/>
      <origin xyz="0.0 0 0" rpy="0 1.5707  0"/>
      <inertia
          ixx="0.1" ixy="0" ixz="0"
          iyy="0.1" iyz="0"
          izz="0.1"
      />
    </inertial>

    <collision name='right_wheel_collision'>
      <origin xyz="0 0 0" rpy="0 1.5707  0"/> 
      <geometry>
        <cylinder radius="0.055" length="0.03"/>
      </geometry>
    </collision>
    <visual name='right_wheel_visual'>
      <origin xyz="0 0 0" rpy="0 1.5707  0"/> 
      <geometry>
        <cylinder radius="0.055" length="0.03"/>
      </geometry>
    </visual>
  </link>
  <joint name="right_wheel_hinge" type="continuous">
    <parent link="robot_base"/>
    <child link="right_wheel"/>
    <origin rpy="0  0  0" xyz="-0.33   0    -0.125"/>
 <axis xyz="1 0 0" rpy="0 0 0"/>
    <limit effort="10000" velocity="1000"/>
    <dynamics damping="1.0" friction="1.0"/>
  </joint>

  <link name="camera">
    <pose>0 0 0 0 0 0</pose>
    <inertial>
      <mass value="0.1"/>
      <origin xyz="0.06 0.06 0.05"/>
      <inertia
          ixx="1e-6" ixy="0" ixz="0"
          iyy="1e-6" iyz="0"
          izz="1e-6"
      />
    </inertial>
    <collision name='camera_collision'>
      <origin xyz="0 0 0" rpy="0 0 0"/> 
      <geometry>
        <box size="0.05 0.05 0.05"/>
      </geometry>
      <mass value="0.1"/>
    </collision>
    <visual name='camera_visual'>
      <origin xyz="0 0 0" rpy="0 0 0"/> 
      <geometry>
        <box size="0.05 0.05 0.05"/>
      </geometry>
      <mass value="0.1"/>
    </visual>
  </link>
  <joint type="fixed" name="camera_joint">
    <origin xyz="0.0 0.285 0.060" rpy="0 0 1.5707"/>
    <child link="camera"/>
    <parent link="robot_base"/>
    <axis xyz="1 0 0" rpy="0 0 0"/>
  </joint>

   <gazebo reference='left_wheel'>
       <material>Gazebo/Red</material>
   </gazebo>
   <gazebo reference='right_wheel'>
       <material>Gazebo/Red</material>
   </gazebo>
   <gazebo reference="robot_base">
       <material>Gazebo/Blue</material>
   </gazebo>
   <gazebo reference="robot_middle_plate">
       <material>Gazebo/Orange</material>
   </gazebo>
   <gazebo reference="robot_top_plate">
       <material>Gazebo/Blue</material>
   </gazebo>
   <gazebo reference="robot_left_support">
       <material>Gazebo/Black</material>
   </gazebo>
   <gazebo reference="robot_right_support">
       <material>Gazebo/Black</material>
   </gazebo>
   <gazebo reference="robot_back_support">
       <material>Gazebo/Black</material>
   </gazebo>
   <gazebo reference="camera">
       <material>Gazebo/Blue</material>
   </gazebo>
   <gazebo reference="laser_scanner">
       <material>Gazebo/Green</material>
   </gazebo>
</robot>
